<?xml version="1.0"?>
<robot name="fruit_harvesting_robot">
  
  <!-- Materials -->
  <material name="blue">
    <color rgba="0.0 0.0 0.8 1.0"/>
  </material>
  <material name="green">
    <color rgba="0.0 0.8 0.0 1.0"/>
  </material>
  <material name="red">
    <color rgba="0.8 0.0 0.0 1.0"/>
  </material>
  <material name="white">
    <color rgba="1.0 1.0 1.0 1.0"/>
  </material>
  <material name="black">
    <color rgba="0.0 0.0 0.0 1.0"/>
  </material>
  <material name="rubber">
    <color rgba="0.4 0.4 0.4 1.0"/>
  </material>
  <material name="silver">
    <color rgba="0.8 0.8 0.8 1.0"/>
  </material>
  <material name="orange">
    <color rgba="1.0 0.5 0.0 1.0"/>
  </material>
  
  <!-- ==================== MOBILE PLATFORM ==================== -->
  <!-- Base Link -->
  <link name="base_link">
    <visual>
      <geometry>
        <box size="0.8 0.6 0.2"/>
      </geometry>
      <material name="blue"/>
      <origin xyz="0 0 0.1" rpy="0 0 0"/>
    </visual>
    <collision>
      <geometry>
        <box size="0.8 0.6 0.2"/>
      </geometry>
      <origin xyz="0 0 0.1" rpy="0 0 0"/>
    </collision>
    <inertial>
      <mass value="50.0"/>
      <inertia ixx="2.0" ixy="0.0" ixz="0.0" iyy="2.0" iyz="0.0" izz="2.0"/>
      <origin xyz="0 0 0.1" rpy="0 0 0"/>
    </inertial>
  </link>
  
  <!-- Wheels -->
  <!-- Front Left Wheel -->
  <link name="front_left_wheel">
    <visual>
      <geometry>
        <cylinder radius="0.1" length="0.05"/>
      </geometry>
      <material name="black"/>
      <origin xyz="0 0 0" rpy="1.57079632679 0 0"/>
    </visual>
    <collision>
      <geometry>
        <cylinder radius="0.1" length="0.05"/>
      </geometry>
      <origin xyz="0 0 0" rpy="1.57079632679 0 0"/>
    </collision>
    <inertial>
      <mass value="2.0"/>
      <inertia ixx="0.01" ixy="0.0" ixz="0.0" iyy="0.01" iyz="0.0" izz="0.01"/>
      <origin xyz="0 0 0" rpy="1.57079632679 0 0"/>
    </inertial>
  </link>
  
  <joint name="front_left_wheel_joint" type="continuous">
    <parent link="base_link"/>
    <child link="front_left_wheel"/>
    <origin xyz="0.3 0.35 0" rpy="0 0 0"/>
    <axis xyz="0 1 0"/>
  </joint>
  
  <!-- Front Right Wheel -->
  <link name="front_right_wheel">
    <visual>
      <geometry>
        <cylinder radius="0.1" length="0.05"/>
      </geometry>
      <material name="black"/>
      <origin xyz="0 0 0" rpy="1.57079632679 0 0"/>
    </visual>
    <collision>
      <geometry>
        <cylinder radius="0.1" length="0.05"/>
      </geometry>
      <origin xyz="0 0 0" rpy="1.57079632679 0 0"/>
    </collision>
    <inertial>
      <mass value="2.0"/>
      <inertia ixx="0.01" ixy="0.0" ixz="0.0" iyy="0.01" iyz="0.0" izz="0.01"/>
      <origin xyz="0 0 0" rpy="1.57079632679 0 0"/>
    </inertial>
  </link>
  
  <joint name="front_right_wheel_joint" type="continuous">
    <parent link="base_link"/>
    <child link="front_right_wheel"/>
    <origin xyz="0.3 -0.35 0" rpy="0 0 0"/>
    <axis xyz="0 1 0"/>
  </joint>
  
  <!-- Rear Left Wheel -->
  <link name="rear_left_wheel">
    <visual>
      <geometry>
        <cylinder radius="0.1" length="0.05"/>
      </geometry>
      <material name="black"/>
      <origin xyz="0 0 0" rpy="1.57079632679 0 0"/>
    </visual>
    <collision>
      <geometry>
        <cylinder radius="0.1" length="0.05"/>
      </geometry>
      <origin xyz="0 0 0" rpy="1.57079632679 0 0"/>
    </collision>
    <inertial>
      <mass value="2.0"/>
      <inertia ixx="0.01" ixy="0.0" ixz="0.0" iyy="0.01" iyz="0.0" izz="0.01"/>
      <origin xyz="0 0 0" rpy="1.57079632679 0 0"/>
    </inertial>
  </link>
  
  <joint name="rear_left_wheel_joint" type="continuous">
    <parent link="base_link"/>
    <child link="rear_left_wheel"/>
    <origin xyz="-0.3 0.35 0" rpy="0 0 0"/>
    <axis xyz="0 1 0"/>
  </joint>
  
  <!-- Rear Right Wheel -->
  <link name="rear_right_wheel">
    <visual>
      <geometry>
        <cylinder radius="0.1" length="0.05"/>
      </geometry>
      <material name="black"/>
      <origin xyz="0 0 0" rpy="1.57079632679 0 0"/>
    </visual>
    <collision>
      <geometry>
        <cylinder radius="0.1" length="0.05"/>
      </geometry>
      <origin xyz="0 0 0" rpy="1.57079632679 0 0"/>
    </collision>
    <inertial>
      <mass value="2.0"/>
      <inertia ixx="0.01" ixy="0.0" ixz="0.0" iyy="0.01" iyz="0.0" izz="0.01"/>
      <origin xyz="0 0 0" rpy="1.57079632679 0 0"/>
    </inertial>
  </link>
  
  <joint name="rear_right_wheel_joint" type="continuous">
    <parent link="base_link"/>
    <child link="rear_right_wheel"/>
    <origin xyz="-0.3 -0.35 0" rpy="0 0 0"/>
    <axis xyz="0 1 0"/>
  </joint>
  
  <!-- Platform to arm connection point -->
  <link name="arm_mount">
    <visual>
      <geometry>
        <cylinder radius="0.1" length="0.1"/>
      </geometry>
      <material name="red"/>
      <origin xyz="0 0 0.05" rpy="0 0 0"/>
    </visual>
    <collision>
      <geometry>
        <cylinder radius="0.1" length="0.1"/>
      </geometry>
      <origin xyz="0 0 0.05" rpy="0 0 0"/>
    </collision>
    <inertial>
      <mass value="1.0"/>
      <inertia ixx="0.01" ixy="0.0" ixz="0.0" iyy="0.01" iyz="0.0" izz="0.01"/>
      <origin xyz="0 0 0.05" rpy="0 0 0"/>
    </inertial>
  </link>
  
  <joint name="arm_mount_joint" type="fixed">
    <parent link="base_link"/>
    <child link="arm_mount"/>
    <origin xyz="0.0 0.0 0.2" rpy="0 0 0"/>
  </joint>
  
  <!-- ==================== ROBOTIC ARM ==================== -->
  <!-- Arm Base -->
  <link name="arm_base">
    <visual>
      <geometry>
        <cylinder radius="0.1" length="0.1"/>
      </geometry>
      <material name="green"/>
      <origin xyz="0 0 0.05" rpy="0 0 0"/>
    </visual>
    <collision>
      <geometry>
        <cylinder radius="0.1" length="0.1"/>
      </geometry>
      <origin xyz="0 0 0.05" rpy="0 0 0"/>
    </collision>
    <inertial>
      <mass value="2.0"/>
      <inertia ixx="0.01" ixy="0.0" ixz="0.0" iyy="0.01" iyz="0.0" izz="0.01"/>
      <origin xyz="0 0 0.05" rpy="0 0 0"/>
    </inertial>
  </link>
  
  <joint name="arm_to_platform" type="revolute">
    <parent link="arm_mount"/>
    <child link="arm_base"/>
    <origin xyz="0 0 0.1" rpy="0 0 0"/>
    <axis xyz="0 0 1"/>
    <limit lower="-3.14159" upper="3.14159" effort="100" velocity="1.0"/>
  </joint>
  
  <!-- Shoulder Link -->
  <link name="shoulder_link">
    <visual>
      <geometry>
        <box size="0.1 0.1 0.3"/>
      </geometry>
      <material name="white"/>
      <origin xyz="0 0 0.15" rpy="0 0 0"/>
    </visual>
    <collision>
      <geometry>
        <box size="0.1 0.1 0.3"/>
      </geometry>
      <origin xyz="0 0 0.15" rpy="0 0 0"/>
    </collision>
    <inertial>
      <mass value="2.0"/>
      <inertia ixx="0.01" ixy="0.0" ixz="0.0" iyy="0.01" iyz="0.0" izz="0.01"/>
      <origin xyz="0 0 0.15" rpy="0 0 0"/>
    </inertial>
  </link>
  
  <joint name="shoulder_joint" type="revolute">
    <parent link="arm_base"/>
    <child link="shoulder_link"/>
    <origin xyz="0 0 0.1" rpy="0 0 0"/>
    <axis xyz="0 1 0"/>
    <limit lower="-1.57079" upper="1.57079" effort="100" velocity="1.0"/>
  </joint>
  
  <!-- Upper Arm Link -->
  <link name="upper_arm_link">
    <visual>
      <geometry>
        <box size="0.6 0.1 0.1"/>
      </geometry>
      <material name="blue"/>
      <origin xyz="0.3 0 0" rpy="0 0 0"/>
    </visual>
    <collision>
      <geometry>
        <box size="0.6 0.1 0.1"/>
      </geometry>
      <origin xyz="0.3 0 0" rpy="0 0 0"/>
    </collision>
    <inertial>
      <mass value="3.0"/>
      <inertia ixx="0.01" ixy="0.0" ixz="0.0" iyy="0.01" iyz="0.0" izz="0.01"/>
      <origin xyz="0.3 0 0" rpy="0 0 0"/>
    </inertial>
  </link>
  
  <joint name="upper_arm_joint" type="revolute">
    <parent link="shoulder_link"/>
    <child link="upper_arm_link"/>
    <origin xyz="0 0 0.3" rpy="0 0 0"/>
    <axis xyz="0 1 0"/>
    <limit lower="-1.57079" upper="1.57079" effort="100" velocity="1.0"/>
  </joint>
  
  <!-- Forearm Link -->
  <link name="forearm_link">
    <visual>
      <geometry>
        <box size="0.5 0.08 0.08"/>
      </geometry>
      <material name="white"/>
      <origin xyz="0.25 0 0" rpy="0 0 0"/>
    </visual>
    <collision>
      <geometry>
        <box size="0.5 0.08 0.08"/>
      </geometry>
      <origin xyz="0.25 0 0" rpy="0 0 0"/>
    </collision>
    <inertial>
      <mass value="2.0"/>
      <inertia ixx="0.01" ixy="0.0" ixz="0.0" iyy="0.01" iyz="0.0" izz="0.01"/>
      <origin xyz="0.25 0 0" rpy="0 0 0"/>
    </inertial>
  </link>
  
  <joint name="elbow_joint" type="revolute">
    <parent link="upper_arm_link"/>
    <child link="forearm_link"/>
    <origin xyz="0.6 0 0" rpy="0 0 0"/>
    <axis xyz="0 1 0"/>
    <limit lower="-2.0" upper="2.0" effort="100" velocity="1.0"/>
  </joint>
  
  <!-- Wrist Link -->
  <link name="wrist_link">
    <visual>
      <geometry>
        <cylinder radius="0.05" length="0.1"/>
      </geometry>
      <material name="green"/>
      <origin xyz="0 0 0" rpy="0 0 0"/>
    </visual>
    <collision>
      <geometry>
        <cylinder radius="0.05" length="0.1"/>
      </geometry>
      <origin xyz="0 0 0" rpy="0 0 0"/>
    </collision>
    <inertial>
      <mass value="1.0"/>
      <inertia ixx="0.01" ixy="0.0" ixz="0.0" iyy="0.01" iyz="0.0" izz="0.01"/>
      <origin xyz="0 0 0" rpy="0 0 0"/>
    </inertial>
  </link>
  
  <joint name="wrist_pitch_joint" type="revolute">
    <parent link="forearm_link"/>
    <child link="wrist_link"/>
    <origin xyz="0.5 0 0" rpy="0 0 0"/>
    <axis xyz="0 1 0"/>
    <limit lower="-1.57079" upper="1.57079" effort="50" velocity="1.0"/>
  </joint>
  
  <!-- Wrist Roll Link -->
  <link name="wrist_roll_link">
    <visual>
      <geometry>
        <cylinder radius="0.04" length="0.08"/>
      </geometry>
      <material name="blue"/>
      <origin xyz="0 0 0.04" rpy="0 0 0"/>
    </visual>
    <collision>
      <geometry>
        <cylinder radius="0.04" length="0.08"/>
      </geometry>
      <origin xyz="0 0 0.04" rpy="0 0 0"/>
    </collision>
    <inertial>
      <mass value="0.5"/>
      <inertia ixx="0.01" ixy="0.0" ixz="0.0" iyy="0.01" iyz="0.0" izz="0.01"/>
      <origin xyz="0 0 0.04" rpy="0 0 0"/>
    </inertial>
  </link>
  
  <!-- Wrist roll joint for rotation around vertical axis -->
  <joint name="wrist_roll_joint" type="continuous">
    <parent link="wrist_link"/>
    <child link="wrist_roll_link"/>
    <origin xyz="0 0 0" rpy="0 0 0"/>
    <axis xyz="0 1 0"/>
    <limit effort="50" velocity="1.0"/>
  </joint>
  
  <!-- Specialized Orange Harvesting End Effector -->
  <link name="gripper_base">
    <visual>
      <geometry>
        <cylinder length="0.05" radius="0.04"/>
      </geometry>
      <material name="silver"/>
      <origin xyz="0 0 0.025" rpy="0 0 0"/>
    </visual>
    <collision>
      <geometry>
        <cylinder length="0.05" radius="0.04"/>
      </geometry>
      <origin xyz="0 0 0.025" rpy="0 0 0"/>
    </collision>
    <inertial>
      <mass value="0.5"/>
      <inertia ixx="0.001" ixy="0" ixz="0" iyy="0.001" iyz="0" izz="0.001"/>
      <origin xyz="0 0 0.025" rpy="0 0 0"/>
    </inertial>
  </link>

  <joint name="gripper_mount" type="fixed">
    <parent link="wrist_roll_link"/>
    <child link="gripper_base"/>
    <origin xyz="0 0 0.08" rpy="0 0 0"/>
  </joint>

  <!-- Rotary mechanism -->
  <link name="rotary_link">
    <visual>
      <geometry>
        <cylinder length="0.03" radius="0.035"/>
      </geometry>
      <material name="black"/>
      <origin xyz="0 0 0.015" rpy="0 0 0"/>
    </visual>
    <collision>
      <geometry>
        <cylinder length="0.03" radius="0.035"/>
      </geometry>
      <origin xyz="0 0 0.015" rpy="0 0 0"/>
    </collision>
    <inertial>
      <mass value="0.3"/>
      <inertia ixx="0.0005" ixy="0" ixz="0" iyy="0.0005" iyz="0" izz="0.0005"/>
      <origin xyz="0 0 0.015" rpy="0 0 0"/>
    </inertial>
  </link>

  <!-- Spin joint for rotation -->
  <joint name="spin_joint" type="continuous">
    <parent link="gripper_base"/>
    <child link="rotary_link"/>
    <origin xyz="0 0 0.05" rpy="0 0 0"/>
    <axis xyz="0 0 1"/>
    <dynamics damping="0.1" friction="0.1"/>
    <limit effort="50" velocity="5"/>
  </joint>

  <!-- Palm -->
  <link name="palm_link">
    <visual>
      <geometry>
        <box size="0.06 0.08 0.02"/>
      </geometry>
      <material name="blue"/>
      <origin xyz="0 0 0.01" rpy="0 0 0"/>
    </visual>
    <collision>
      <geometry>
        <box size="0.06 0.08 0.02"/>
      </geometry>
      <origin xyz="0 0 0.01" rpy="0 0 0"/>
    </collision>
    <inertial>
      <mass value="0.2"/>
      <inertia ixx="0.0003" ixy="0" ixz="0" iyy="0.0003" iyz="0" izz="0.0003"/>
      <origin xyz="0 0 0.01" rpy="0 0 0"/>
    </inertial>
  </link>

  <joint name="rotary_to_palm" type="fixed">
    <parent link="rotary_link"/>
    <child link="palm_link"/>
    <origin xyz="0 0 0.03" rpy="0 0 0"/>
  </joint>

  <!-- Fingers with pads -->
  <link name="left_finger_link">
    <visual>
      <geometry>
        <box size="0.02 0.08 0.12"/>
      </geometry>
      <material name="blue"/>
      <origin xyz="0 0 0.06" rpy="0 0 0"/>
    </visual>
    <collision>
      <geometry>
        <box size="0.02 0.08 0.12"/>
      </geometry>
      <origin xyz="0 0 0.06" rpy="0 0 0"/>
    </collision>
    <inertial>
      <mass value="0.1"/>
      <inertia ixx="0.0001" ixy="0" ixz="0" iyy="0.0001" iyz="0" izz="0.0001"/>
      <origin xyz="0 0 0.06" rpy="0 0 0"/>
    </inertial>
  </link>

  <link name="right_finger_link">
    <visual>
      <geometry>
        <box size="0.02 0.08 0.12"/>
      </geometry>
      <material name="blue"/>
      <origin xyz="0 0 0.06" rpy="0 0 0"/>
    </visual>
    <collision>
      <geometry>
        <box size="0.02 0.08 0.12"/>
      </geometry>
      <origin xyz="0 0 0.06" rpy="0 0 0"/>
    </collision>
    <inertial>
      <mass value="0.1"/>
      <inertia ixx="0.0001" ixy="0" ixz="0" iyy="0.0001" iyz="0" izz="0.0001"/>
      <origin xyz="0 0 0.06" rpy="0 0 0"/>
    </inertial>
  </link>

  <!-- Finger pads -->
  <link name="left_pad_link">
    <visual>
      <geometry>
        <cylinder length="0.01" radius="0.015"/>
      </geometry>
      <material name="orange"/>
      <origin xyz="0 0 0.005" rpy="1.5708 0 0"/>
    </visual>
    <collision>
      <geometry>
        <cylinder length="0.01" radius="0.015"/>
      </geometry>
      <origin xyz="0 0 0.005" rpy="1.5708 0 0"/>
    </collision>
    <inertial>
      <mass value="0.02"/>
      <inertia ixx="0.00001" ixy="0" ixz="0" iyy="0.00001" iyz="0" izz="0.00001"/>
      <origin xyz="0 0 0.005" rpy="1.5708 0 0"/>
    </inertial>
  </link>

  <link name="right_pad_link">
    <visual>
      <geometry>
        <cylinder length="0.01" radius="0.015"/>
      </geometry>
      <material name="orange"/>
      <origin xyz="0 0 0.005" rpy="1.5708 0 0"/>
    </visual>
    <collision>
      <geometry>
        <cylinder length="0.01" radius="0.015"/>
      </geometry>
      <origin xyz="0 0 0.005" rpy="1.5708 0 0"/>
    </collision>
    <inertial>
      <mass value="0.02"/>
      <inertia ixx="0.00001" ixy="0" ixz="0" iyy="0.00001" iyz="0" izz="0.00001"/>
      <origin xyz="0 0 0.005" rpy="1.5708 0 0"/>
    </inertial>
  </link>

  <!-- Finger joints -->
  <joint name="left_finger_joint" type="prismatic">
    <parent link="palm_link"/>
    <child link="left_finger_link"/>
    <origin xyz="-0.04 0 0.02" rpy="0 0 0"/>
    <axis xyz="1 0 0"/>
    <limit lower="0" upper="0.03" effort="50" velocity="1"/>
    <dynamics damping="0.5" friction="0.5"/>
  </joint>

  <joint name="right_finger_joint" type="prismatic">
    <parent link="palm_link"/>
    <child link="right_finger_link"/>
    <origin xyz="0.04 0 0.02" rpy="0 0 0"/>
    <axis xyz="-1 0 0"/>
    <limit lower="0" upper="0.03" effort="50" velocity="1"/>
    <dynamics damping="0.5" friction="0.5"/>
  </joint>

  <!-- Pad joints -->
  <joint name="left_finger_pad_joint" type="fixed">
    <parent link="left_finger_link"/>
    <child link="left_pad_link"/>
    <origin xyz="0.01 0 0.06" rpy="0 0 0"/>
  </joint>

  <joint name="right_finger_pad_joint" type="fixed">
    <parent link="right_finger_link"/>
    <child link="right_pad_link"/>
    <origin xyz="-0.01 0 0.06" rpy="0 0 0"/>
  </joint>

  <!-- Cutter -->
  <link name="cutter_link">
    <visual>
      <geometry>
        <cylinder length="0.01" radius="0.01"/>
      </geometry>
      <material name="silver"/>
      <origin xyz="0 0 0.005" rpy="0 0 0"/>
    </visual>
    <collision>
      <geometry>
        <cylinder length="0.01" radius="0.01"/>
      </geometry>
      <origin xyz="0 0 0.005" rpy="0 0 0"/>
    </collision>
    <inertial>
      <mass value="0.05"/>
      <inertia ixx="0.00001" ixy="0" ixz="0" iyy="0.00001" iyz="0" izz="0.00001"/>
      <origin xyz="0 0 0.005" rpy="0 0 0"/>
    </inertial>
  </link>

  <joint name="cutter_joint" type="fixed">
    <parent link="palm_link"/>
    <child link="cutter_link"/>
    <origin xyz="0 0.04 0.02" rpy="0 0 0"/>
  </joint>
  
  <!-- Transmission Elements for Control -->
  <transmission name="arm_to_platform_trans">
    <type>transmission_interface/SimpleTransmission</type>
    <joint name="arm_to_platform">
      <hardwareInterface>hardware_interface/PositionJointInterface</hardwareInterface>
    </joint>
    <actuator name="arm_to_platform_motor">
      <mechanicalReduction>1</mechanicalReduction>
      <hardwareInterface>hardware_interface/PositionJointInterface</hardwareInterface>
    </actuator>
  </transmission>
  
  <transmission name="shoulder_joint_trans">
    <type>transmission_interface/SimpleTransmission</type>
    <joint name="shoulder_joint">
      <hardwareInterface>hardware_interface/PositionJointInterface</hardwareInterface>
    </joint>
    <actuator name="shoulder_motor">
      <mechanicalReduction>1</mechanicalReduction>
      <hardwareInterface>hardware_interface/PositionJointInterface</hardwareInterface>
    </actuator>
  </transmission>
  
  <transmission name="upper_arm_joint_trans">
    <type>transmission_interface/SimpleTransmission</type>
    <joint name="upper_arm_joint">
      <hardwareInterface>hardware_interface/PositionJointInterface</hardwareInterface>
    </joint>
    <actuator name="upper_arm_motor">
      <mechanicalReduction>1</mechanicalReduction>
      <hardwareInterface>hardware_interface/PositionJointInterface</hardwareInterface>
    </actuator>
  </transmission>
  
  <transmission name="elbow_joint_trans">
    <type>transmission_interface/SimpleTransmission</type>
    <joint name="elbow_joint">
      <hardwareInterface>hardware_interface/PositionJointInterface</hardwareInterface>
    </joint>
    <actuator name="elbow_motor">
      <mechanicalReduction>1</mechanicalReduction>
      <hardwareInterface>hardware_interface/PositionJointInterface</hardwareInterface>
    </actuator>
  </transmission>
  
  <transmission name="wrist_pitch_joint_trans">
    <type>transmission_interface/SimpleTransmission</type>
    <joint name="wrist_pitch_joint">
      <hardwareInterface>hardware_interface/PositionJointInterface</hardwareInterface>
    </joint>
    <actuator name="wrist_pitch_motor">
      <mechanicalReduction>1</mechanicalReduction>
      <hardwareInterface>hardware_interface/PositionJointInterface</hardwareInterface>
    </actuator>
  </transmission>
  
  <transmission name="wrist_roll_joint_trans">
    <type>transmission_interface/SimpleTransmission</type>
    <joint name="wrist_roll_joint">
      <hardwareInterface>hardware_interface/PositionJointInterface</hardwareInterface>
    </joint>
    <actuator name="wrist_roll_motor">
      <mechanicalReduction>1</mechanicalReduction>
      <hardwareInterface>hardware_interface/PositionJointInterface</hardwareInterface>
    </actuator>
  </transmission>
  
  <!-- Fruit Gripper Transmissions -->
  <!-- Fruit Gripper Transmissions -->
  <transmission name="spin_joint_trans">
    <type>transmission_interface/SimpleTransmission</type>
    <joint name="spin_joint">
      <hardwareInterface>hardware_interface/VelocityJointInterface</hardwareInterface>
    </joint>
    <actuator name="spin_motor">
      <mechanicalReduction>1</mechanicalReduction>
      <hardwareInterface>hardware_interface/VelocityJointInterface</hardwareInterface>
    </actuator>
  </transmission>

  <transmission name="left_finger_trans">
    <type>transmission_interface/SimpleTransmission</type>
    <joint name="left_finger_joint">
      <hardwareInterface>hardware_interface/PositionJointInterface</hardwareInterface>
    </joint>
    <actuator name="left_finger_motor">
      <mechanicalReduction>1</mechanicalReduction>
      <hardwareInterface>hardware_interface/PositionJointInterface</hardwareInterface>
    </actuator>
  </transmission>

  <transmission name="right_finger_trans">
    <type>transmission_interface/SimpleTransmission</type>
    <joint name="right_finger_joint">
      <hardwareInterface>hardware_interface/PositionJointInterface</hardwareInterface>
    </joint>
    <actuator name="right_finger_motor">
      <mechanicalReduction>1</mechanicalReduction>
      <hardwareInterface>hardware_interface/PositionJointInterface</hardwareInterface>
    </actuator>
  </transmission>
  
  <!-- Wheel Transmissions -->
  <transmission name="front_left_wheel_trans">
    <type>transmission_interface/SimpleTransmission</type>
    <joint name="front_left_wheel_joint">
      <hardwareInterface>hardware_interface/VelocityJointInterface</hardwareInterface>
    </joint>
    <actuator name="front_left_wheel_motor">
      <mechanicalReduction>1</mechanicalReduction>
      <hardwareInterface>hardware_interface/VelocityJointInterface</hardwareInterface>
    </actuator>
  </transmission>
  
  <transmission name="front_right_wheel_trans">
    <type>transmission_interface/SimpleTransmission</type>
    <joint name="front_right_wheel_joint">
      <hardwareInterface>hardware_interface/VelocityJointInterface</hardwareInterface>
    </joint>
    <actuator name="front_right_wheel_motor">
      <mechanicalReduction>1</mechanicalReduction>
      <hardwareInterface>hardware_interface/VelocityJointInterface</hardwareInterface>
    </actuator>
  </transmission>
  
  <transmission name="rear_left_wheel_trans">
    <type>transmission_interface/SimpleTransmission</type>
    <joint name="rear_left_wheel_joint">
      <hardwareInterface>hardware_interface/VelocityJointInterface</hardwareInterface>
    </joint>
    <actuator name="rear_left_wheel_motor">
      <mechanicalReduction>1</mechanicalReduction>
      <hardwareInterface>hardware_interface/VelocityJointInterface</hardwareInterface>
    </actuator>
  </transmission>
  
  <transmission name="rear_right_wheel_trans">
    <type>transmission_interface/SimpleTransmission</type>
    <joint name="rear_right_wheel_joint">
      <hardwareInterface>hardware_interface/VelocityJointInterface</hardwareInterface>
    </joint>
    <actuator name="rear_right_wheel_motor">
      <mechanicalReduction>1</mechanicalReduction>
      <hardwareInterface>hardware_interface/VelocityJointInterface</hardwareInterface>
    </actuator>
  </transmission>
  
  <!-- Gazebo Plugin for ROS Control -->
  <gazebo>
    <plugin name="gazebo_ros_control" filename="libgazebo_ros_control.so">
      <robotNamespace>/fruit_harvesting_robot</robotNamespace>
      <robotSimType>gazebo_ros_control/DefaultRobotHWSim</robotSimType>
    </plugin>
  </gazebo>

  <!-- Material properties for the rubber padding -->
  <gazebo reference="finger_1">
    <material>Gazebo/Grey</material>
    <mu1>1.2</mu1>
    <mu2>1.2</mu2>
    <kp>1000000.0</kp>
    <kd>1.0</kd>
    <maxVel>0.1</maxVel>
    <minDepth>0.001</minDepth>
  </gazebo>

  <gazebo reference="finger_2">
    <material>Gazebo/Grey</material>
    <mu1>1.2</mu1>
    <mu2>1.2</mu2>
    <kp>1000000.0</kp>
    <kd>1.0</kd>
    <maxVel>0.1</maxVel>
    <minDepth>0.001</minDepth>
  </gazebo>

  <gazebo reference="finger_3">
    <material>Gazebo/Grey</material>
    <mu1>1.2</mu1>
    <mu2>1.2</mu2>
    <kp>1000000.0</kp>
    <kd>1.0</kd>
    <maxVel>0.1</maxVel>
    <minDepth>0.001</minDepth>
  </gazebo>

</robot>