<?xml version="1.0"?>
<robot name="orange_harvester_gripper">
  <!-- Materials -->
  <material name="blue">
    <color rgba="0.0 0.0 0.8 1.0"/>
  </material>
  <material name="silver">
    <color rgba="0.8 0.8 0.8 1.0"/>
  </material>
  <material name="black">
    <color rgba="0.1 0.1 0.1 1.0"/>
  </material>
  <material name="orange">
    <color rgba="1.0 0.5 0.0 1.0"/>
  </material>

  <!-- Base link for the end effector, connects to the robot arm -->
  <link name="base_link">
    <visual>
      <geometry>
        <cylinder length="0.05" radius="0.04"/>
      </geometry>
      <material name="silver"/>
      <origin xyz="0 0 0.025" rpy="0 0 0"/>
    </visual>
    <collision>
      <geometry>
        <cylinder length="0.05" radius="0.04"/>
      </geometry>
      <origin xyz="0 0 0.025" rpy="0 0 0"/>
    </collision>
    <inertial>
      <mass value="0.5"/>
      <inertia ixx="0.001" ixy="0" ixz="0" iyy="0.001" iyz="0" izz="0.001"/>
      <origin xyz="0 0 0.025" rpy="0 0 0"/>
    </inertial>
  </link>

  <!-- Rotary mechanism link -->
  <link name="rotary_link">
    <visual>
      <geometry>
        <cylinder length="0.03" radius="0.035"/>
      </geometry>
      <material name="black"/>
      <origin xyz="0 0 0.015" rpy="0 0 0"/>
    </visual>
    <collision>
      <geometry>
        <cylinder length="0.03" radius="0.035"/>
      </geometry>
      <origin xyz="0 0 0.015" rpy="0 0 0"/>
    </collision>
    <inertial>
      <mass value="0.3"/>
      <inertia ixx="0.0005" ixy="0" ixz="0" iyy="0.0005" iyz="0" izz="0.0005"/>
      <origin xyz="0 0 0.015" rpy="0 0 0"/>
    </inertial>
  </link>

  <!-- Rotary joint for spinning motion -->
  <joint name="spin_joint" type="continuous">
    <parent link="base_link"/>
    <child link="rotary_link"/>
    <origin xyz="0 0 0.05" rpy="0 0 0"/>
    <axis xyz="0 0 1"/>
    <dynamics damping="0.1" friction="0.1"/>
    <limit effort="50" velocity="5"/>
  </joint>

  <!-- Gripper palm link -->
  <link name="palm_link">
    <visual>
      <geometry>
        <box size="0.06 0.08 0.02"/>
      </geometry>
      <material name="blue"/>
      <origin xyz="0 0 0.01" rpy="0 0 0"/>
    </visual>
    <collision>
      <geometry>
        <box size="0.06 0.08 0.02"/>
      </geometry>
      <origin xyz="0 0 0.01" rpy="0 0 0"/>
    </collision>
    <inertial>
      <mass value="0.2"/>
      <inertia ixx="0.0003" ixy="0" ixz="0" iyy="0.0003" iyz="0" izz="0.0003"/>
      <origin xyz="0 0 0.01" rpy="0 0 0"/>
    </inertial>
  </link>

  <!-- Fixed joint connecting rotary to palm -->
  <joint name="rotary_to_palm" type="fixed">
    <parent link="rotary_link"/>
    <child link="palm_link"/>
    <origin xyz="0 0 0.03" rpy="0 0 0"/>
  </joint>

  <!-- Left finger link -->
  <link name="left_finger_link">
    <visual>
      <geometry>
        <box size="0.02 0.08 0.12"/>
      </geometry>
      <material name="blue"/>
      <origin xyz="0 0 0.06" rpy="0 0 0"/>
    </visual>
    <collision>
      <geometry>
        <box size="0.02 0.08 0.12"/>
      </geometry>
      <origin xyz="0 0 0.06" rpy="0 0 0"/>
    </collision>
    <inertial>
      <mass value="0.1"/>
      <inertia ixx="0.0001" ixy="0" ixz="0" iyy="0.0001" iyz="0" izz="0.0001"/>
      <origin xyz="0 0 0.06" rpy="0 0 0"/>
    </inertial>
  </link>

  <!-- Right finger link -->
  <link name="right_finger_link">
    <visual>
      <geometry>
        <box size="0.02 0.08 0.12"/>
      </geometry>
      <material name="blue"/>
      <origin xyz="0 0 0.06" rpy="0 0 0"/>
    </visual>
    <collision>
      <geometry>
        <box size="0.02 0.08 0.12"/>
      </geometry>
      <origin xyz="0 0 0.06" rpy="0 0 0"/>
    </collision>
    <inertial>
      <mass value="0.1"/>
      <inertia ixx="0.0001" ixy="0" ixz="0" iyy="0.0001" iyz="0" izz="0.0001"/>
      <origin xyz="0 0 0.06" rpy="0 0 0"/>
    </inertial>
  </link>

  <!-- Left finger pad link -->
  <link name="left_pad_link">
    <visual>
      <geometry>
        <cylinder length="0.01" radius="0.015"/>
      </geometry>
      <material name="orange"/>
      <origin xyz="0 0 0.005" rpy="1.5708 0 0"/>
    </visual>
    <collision>
      <geometry>
        <cylinder length="0.01" radius="0.015"/>
      </geometry>
      <origin xyz="0 0 0.005" rpy="1.5708 0 0"/>
    </collision>
    <inertial>
      <mass value="0.02"/>
      <inertia ixx="0.00001" ixy="0" ixz="0" iyy="0.00001" iyz="0" izz="0.00001"/>
      <origin xyz="0 0 0.005" rpy="1.5708 0 0"/>
    </inertial>
  </link>

  <!-- Right finger pad link -->
  <link name="right_pad_link">
    <visual>
      <geometry>
        <cylinder length="0.01" radius="0.015"/>
      </geometry>
      <material name="orange"/>
      <origin xyz="0 0 0.005" rpy="1.5708 0 0"/>
    </visual>
    <collision>
      <geometry>
        <cylinder length="0.01" radius="0.015"/>
      </geometry>
      <origin xyz="0 0 0.005" rpy="1.5708 0 0"/>
    </collision>
    <inertial>
      <mass value="0.02"/>
      <inertia ixx="0.00001" ixy="0" ixz="0" iyy="0.00001" iyz="0" izz="0.00001"/>
      <origin xyz="0 0 0.005" rpy="1.5708 0 0"/>
    </inertial>
  </link>

  <!-- Prismatic joint for left finger -->
  <joint name="left_finger_joint" type="prismatic">
    <parent link="palm_link"/>
    <child link="left_finger_link"/>
    <origin xyz="-0.04 0 0.02" rpy="0 0 0"/>
    <axis xyz="1 0 0"/>
    <limit lower="0" upper="0.03" effort="50" velocity="1"/>
    <dynamics damping="0.5" friction="0.5"/>
  </joint>

  <!-- Prismatic joint for right finger -->
  <joint name="right_finger_joint" type="prismatic">
    <parent link="palm_link"/>
    <child link="right_finger_link"/>
    <origin xyz="0.04 0 0.02" rpy="0 0 0"/>
    <axis xyz="-1 0 0"/>
    <limit lower="0" upper="0.03" effort="50" velocity="1"/>
    <dynamics damping="0.5" friction="0.5"/>
  </joint>

  <!-- Fixed joint for left finger pad -->
  <joint name="left_finger_pad_joint" type="fixed">
    <parent link="left_finger_link"/>
    <child link="left_pad_link"/>
    <origin xyz="0.01 0 0.06" rpy="0 0 0"/>
  </joint>

  <!-- Fixed joint for right finger pad -->
  <joint name="right_finger_pad_joint" type="fixed">
    <parent link="right_finger_link"/>
    <child link="right_pad_link"/>
    <origin xyz="-0.01 0 0.06" rpy="0 0 0"/>
  </joint>

  <!-- Sharp cutter link for stem cutting -->
  <link name="cutter_link">
    <visual>
      <geometry>
        <cylinder length="0.01" radius="0.01"/>
      </geometry>
      <material name="silver"/>
      <origin xyz="0 0 0.005" rpy="0 0 0"/>
    </visual>
    <collision>
      <geometry>
        <cylinder length="0.01" radius="0.01"/>
      </geometry>
      <origin xyz="0 0 0.005" rpy="0 0 0"/>
    </collision>
    <inertial>
      <mass value="0.05"/>
      <inertia ixx="0.00001" ixy="0" ixz="0" iyy="0.00001" iyz="0" izz="0.00001"/>
      <origin xyz="0 0 0.005" rpy="0 0 0"/>
    </inertial>
  </link>
  
  <!-- Fixed joint for cutter -->
  <joint name="cutter_joint" type="fixed">
    <parent link="palm_link"/>
    <child link="cutter_link"/>
    <origin xyz="0 0.04 0.02" rpy="0 0 0"/>
  </joint>

  <!-- Transmission for left finger -->
  <transmission name="left_finger_trans">
    <type>transmission_interface/SimpleTransmission</type>
    <joint name="left_finger_joint">
      <hardwareInterface>hardware_interface/PositionJointInterface</hardwareInterface>
    </joint>
    <actuator name="left_finger_motor">
      <hardwareInterface>hardware_interface/PositionJointInterface</hardwareInterface>
      <mechanicalReduction>1</mechanicalReduction>
    </actuator>
  </transmission>

  <!-- Transmission for right finger -->
  <transmission name="right_finger_trans">
    <type>transmission_interface/SimpleTransmission</type>
    <joint name="right_finger_joint">
      <hardwareInterface>hardware_interface/PositionJointInterface</hardwareInterface>
    </joint>
    <actuator name="right_finger_motor">
      <hardwareInterface>hardware_interface/PositionJointInterface</hardwareInterface>
      <mechanicalReduction>1</mechanicalReduction>
    </actuator>
  </transmission>

  <!-- Transmission for spin joint -->
  <transmission name="spin_joint_trans">
    <type>transmission_interface/SimpleTransmission</type>
    <joint name="spin_joint">
      <hardwareInterface>hardware_interface/VelocityJointInterface</hardwareInterface>
    </joint>
    <actuator name="spin_motor">
      <hardwareInterface>hardware_interface/VelocityJointInterface</hardwareInterface>
      <mechanicalReduction>1</mechanicalReduction>
    </actuator>
  </transmission>
</robot>